#VRML_SIM R2023a utf8
PROTO FourWheelsRobot [
  field SFVec3f    translation  0 0 0
  field SFRotation rotation     0 0 1 0
  field SFFloat    bodyMass     1
]
{
    Robot {
        translation IS translation
        rotation IS rotation
        children [
          DEF distSens2 DistanceSensor {
            translation 0.05 0.025 0
            rotation 0 0 1 0.5
            children [
              DEF sens_cube_shape Shape {
                appearance PBRAppearance {
                  baseColor 0 0 1
                  roughness 1
                  metalness 0
                }
                geometry Box {
                  size 0.01 0.01 0.01
                }
              }
            ]
            name "ds_left"
            boundingObject USE sens_cube_shape
          }
          DEF distSens1 DistanceSensor {
            translation 0.05 -0.025 0
            rotation 0 0 1 -0.5
            children [
              USE sens_cube_shape
            ]
            name "ds_right"
            boundingObject USE sens_cube_shape
          }
          DEF distSens3 DistanceSensor {
            translation 0 0.035 -0.005
            rotation 0 0 1 1.5708
            children [
              USE sens_cube_shape
            ]
            name "ds_side_left"
            boundingObject USE sens_cube_shape
          }
          DEF distSens4 DistanceSensor {
            translation 0 -0.035 -0.005
            rotation 0 0 1 -1.5708
            children [
              USE sens_cube_shape
            ]
            name "ds_side_right"
            boundingObject USE sens_cube_shape
          }
          DEF gps1 GPS {
            translation 0 0.035 0.005
            children [
              DEF gps_shape Shape {
                appearance PBRAppearance {
                  baseColor 1 0.666667 0
                  roughness 1
                  metalness 0
                }
                geometry Box {
                  size 0.01 0.01 0.01
                }
              }
            ]
            name "gps1"
            boundingObject USE gps_shape
          }
          DEF gps2 GPS {
            translation 0 -0.035 0.005
            children [
              USE gps_shape
            ]
            name "gps2"
            boundingObject USE gps_shape
          }
          DEF BODY Shape {
            appearance PBRAppearance {
              baseColor 1 0 0
              roughness 1
              metalness 0
            }
            geometry Box {
              size 0.1 0.07 0.03
            }
          }
          DEF wheel1_hingeJoint HingeJoint {
            jointParameters HingeJointParameters {
              position -2.9305912797393097e-10
              axis 0 1 0
              anchor 0.03 0.04 -0.01
            }
            device [
              RotationalMotor {
                name "wheel1"
              }
            ]
            endPoint DEF WHEEL1 Solid {
              translation 0.03 0.04 -0.01
              rotation 1 -6.593805403371778e-09 6.593826558842626e-09 1.5707999999997482
              children [
                DEF WHEEL Shape {
                  appearance PBRAppearance {
                    baseColor 0 1 0
                    roughness 1
                    metalness 0
                  }
                  geometry Cylinder {
                    height 0.01
                    radius 0.02
                    subdivision 24
                  }
                }
              ]
              name "wheel1_hinge"
              boundingObject USE WHEEL
              physics DEF WHEEL_PH Physics {
              }
            }
          }
          DEF wheel2_hingeJoint HingeJoint {
              jointParameters HingeJointParameters {
              position -2.955246077300105e-10
              axis 0 1 0
              anchor 0.03 -0.04 -0.01
            }
            device [
              RotationalMotor {
                name "wheel2"
              }
            ]
            endPoint DEF WHEEL2 Solid {
              translation 0.03 -0.04 -0.01
              rotation 1 -6.649280170467025e-09 6.649305530455585e-09 1.5707999999997648
              children [
                USE WHEEL
              ]
              name "wheel2_hinge"
              boundingObject USE WHEEL
              physics USE WHEEL_PH
            }
          }
          DEF wheel3_hingeJoint HingeJoint {
            jointParameters HingeJointParameters {
              position 2.9558414171520647e-10
              axis 0 1 0
              anchor -0.03 0.04 -0.01
            }
            device [
              RotationalMotor {
                name "wheel3"
              }
            ]
            endPoint DEF WHEEL3 Solid {
              translation -0.03 0.04 -0.01
              rotation 1 6.650612542540222e-09 -6.650641239078467e-09 1.5707999999997309
              children [
                USE WHEEL
              ]
              name "wheel3_hinge"
              boundingObject USE WHEEL
              physics USE WHEEL_PH
            }
          }
          DEF wheel4_hingeJoint HingeJoint {
            jointParameters HingeJointParameters {
              position -2.9795362253203856e-10
              axis 0 1 0
              anchor -0.03 -0.04 -0.01
            }
            device [
              RotationalMotor {
                name "wheel4"
              }
            ]
            endPoint DEF WHEEL4 Solid {
              translation -0.03 -0.04 -0.01
              rotation 1 -6.703932966485886e-09 6.703957869721757e-09 1.5707999999997222
              children [
                USE WHEEL
              ]
              name "wheel4_hinge"
              boundingObject USE WHEEL
              physics USE WHEEL_PH
            }
          }
        ]
        boundingObject USE BODY
        physics Physics {
        }
        controller "astar_gps"
      }
}
