#VRML_SIM R2023a utf8
PROTO FourWheelsRound [
  field SFVec3f    translation  0 0 0
  field SFRotation rotation     0 0 1 0
  field SFFloat    bodyMass     1
]
{
    Robot {
        translation IS translation
        rotation IS rotation
          children [
    DEF cylinder Transform {
      translation 0 0 0.02
      children [
        DEF cylinder_shape Shape {
          appearance PBRAppearance {
            baseColor 0 1 1
            roughness 1
            metalness 0
          }
          geometry Cylinder {
            height 0.015
            radius 0.05
          }
        }
      ]
    }
    DEF distSens_R0 DistanceSensor {
      translation 0 -0.05 0.02
      rotation 0 0 1 -1.5708
      children [
        DEF sens_cube_shape Shape {
          appearance PBRAppearance {
            baseColor 0 0 1
            roughness 1
            metalness 0
          }
          geometry Box {
            size 0.01 0.01 0.01
          }
        }
      ]
      name "ds_R0"
      boundingObject USE sens_cube_shape
    }
    DEF distSens_R1 DistanceSensor {
      translation 0.025 -0.044 0.02
      rotation 0 0 1 -1.0472
      children [
        USE sens_cube_shape
      ]
      name "ds_R1"
      boundingObject USE sens_cube_shape
    }
    DEF distSens_R2 DistanceSensor {
      translation 0.044 -0.025 0.02
      rotation 0 0 1 -0.523599
      children [
        DEF sens_cube_shape Shape {
          appearance PBRAppearance {
            baseColor 0 0 1
            roughness 1
            metalness 0
          }
          geometry Box {
            size 0.01 0.01 0.01
          }
        }
      ]
      name "ds_R2"
      boundingObject USE sens_cube_shape
    }
    DEF distSens_mid DistanceSensor {
      translation 0.05 0 0.02
      children [
        USE sens_cube_shape
      ]
      name "ds_mid"
      boundingObject USE sens_cube_shape
    }
    DEF distSens_L2 DistanceSensor {
      translation 0.044 0.025 0.02
      rotation 0 0 1 0.523599
      children [
        USE sens_cube_shape
      ]
      name "ds_L2"
      boundingObject USE sens_cube_shape
    }
    DEF distSens_L1 DistanceSensor {
      translation 0.025 0.044 0.02
      rotation 0 0 1 1.0472
      children [
        USE sens_cube_shape
      ]
      name "ds_L1"
      boundingObject USE sens_cube_shape
    }
    DEF distSens_L0 DistanceSensor {
      translation 0 0.05 0.02
      rotation 0 0 1 1.5708
      children [
        USE sens_cube_shape
      ]
      name "ds_L0"
      boundingObject USE sens_cube_shape
    }
    DEF gps1 GPS {
      translation 0 0.04 0.03
      children [
        DEF gps_shape Shape {
          appearance PBRAppearance {
            baseColor 1 0.666667 0
            roughness 1
            metalness 0
          }
          geometry Box {
            size 0.01 0.01 0.01
          }
        }
      ]
      name "gps1"
      boundingObject USE gps_shape
    }
    DEF gps2 GPS {
      translation 0 -0.04 0.03
      children [
        USE gps_shape
      ]
      name "gps2"
      boundingObject USE gps_shape
    }
    DEF BODY Shape {
      appearance PBRAppearance {
        baseColor 1 0 0
        roughness 1
        metalness 0
      }
      geometry Box {
        size 0.07 0.04 0.03
      }
    }
    DEF wheel1_hingeJoint HingeJoint {
      jointParameters HingeJointParameters {
        axis 0 1 0
        anchor 0.02 0.03 -0.01
      }
      device [
        RotationalMotor {
          name "wheel1"
        }
      ]
      endPoint DEF WHEEL1 Solid {
        translation 0.02 0.025 -0.01
        rotation 1 0 0 1.5707999999999998
        children [
          DEF WHEEL Shape {
            appearance PBRAppearance {
              baseColor 0 1 0
              roughness 1
              metalness 0
            }
            geometry Cylinder {
              height 0.01
              radius 0.019
              subdivision 24
            }
          }
        ]
        name "wheel1_solid"
        boundingObject USE WHEEL
        physics DEF WHEEL_PH Physics {
        }
      }
    }
    DEF wheel2_hingeJoint HingeJoint {
      jointParameters HingeJointParameters {
        position 213.26058158940975
        axis 0 1 0
        anchor 0.02 -0.03 -0.01
      }
      device [
        RotationalMotor {
          name "wheel2"
        }
      ]
      endPoint DEF WHEEL2 Solid {
        translation 0.02 -0.025 -0.01
        rotation 1 -2.3551343625838557e-16 1.5700895750559036e-16 1.5707999999999998
        children [
          USE WHEEL
        ]
        name "wheel2_solid"
        boundingObject USE WHEEL
        physics USE WHEEL_PH
      }
    }
    DEF wheel3_hingeJoint HingeJoint {
      jointParameters HingeJointParameters {
        position 104.49386043345592
        axis 0 1 0
        anchor -0.02 0.03 -0.01
      }
      device [
        RotationalMotor {
          name "wheel3"
        }
      ]
      endPoint DEF WHEEL3 Solid {
        translation -0.02 0.025 -0.01
        rotation 1 0 0 1.5707999999999998
        children [
          USE WHEEL
        ]
        name "wheel3_solid"
        boundingObject USE WHEEL
        physics USE WHEEL_PH
      }
    }
    DEF wheel4_hingeJoint HingeJoint {
      jointParameters HingeJointParameters {
        position 213.26056795446084
        axis 0 1 0
        anchor -0.02 -0.03 -0.01
      }
      device [
        RotationalMotor {
          name "wheel4"
        }
      ]
      endPoint DEF WHEEL4 Solid {
        translation -0.02 -0.025 -0.01
        rotation 1 -2.355134362583857e-16 -3.9252239376397615e-17 1.5707999999999984
        children [
          USE WHEEL
        ]
        name "wheel4_solid"
        boundingObject USE WHEEL
        physics USE WHEEL_PH
      }
    }
  ]
  boundingObject USE cylinder_shape
  physics Physics {
  }
  controller "astar_gps"
}

}